Workbook
Name \a: #REF!
Name __________________num031: IF(ISERROR(FIND(")+",Text03,230)),LEN(Text03),FIND(")+",Text03,230))
Name __________________num032: IF(ISERROR(FIND(")+",text03_1,230)),LEN(text03_1),FIND(")+",text03_1,230))
Name __________________num033: IF(ISERROR(FIND(")+",text03_2,230)),LEN(text03_2),FIND(")+",text03_2,230))
Name __________________num1: IF(ISERROR(FIND(")+",_xleta.TEXT,230)),LEN(_xleta.TEXT),FIND(")+",_xleta.TEXT,230))
Name __________________num2: IF(ISERROR(FIND(")+",text_1,230)),LEN(text_1),FIND(")+",text_1,230))
Name __________________num3: IF(ISERROR(FIND(")+",text_2,230)),LEN(text_2),FIND(")+",text_2,230))
Name _________________num031: IF(ISERROR(FIND(")+",Text03,230)),LEN(Text03),FIND(")+",Text03,230))
Name _________________num032: IF(ISERROR(FIND(")+",text03_1,230)),LEN(text03_1),FIND(")+",text03_1,230))
Name _________________num033: IF(ISERROR(FIND(")+",text03_2,230)),LEN(text03_2),FIND(")+",text03_2,230))
Name _________________num1: IF(ISERROR(FIND(")+",_xleta.TEXT,230)),LEN(_xleta.TEXT),FIND(")+",_xleta.TEXT,230))
Name _________________num2: IF(ISERROR(FIND(")+",text_1,230)),LEN(text_1),FIND(")+",text_1,230))
Name _________________num3: IF(ISERROR(FIND(")+",text_2,230)),LEN(text_2),FIND(")+",text_2,230))
Name ________________num031: IF(ISERROR(FIND(")+",Text03,230)),LEN(Text03),FIND(")+",Text03,230))
Name ________________num032: IF(ISERROR(FIND(")+",text03_1,230)),LEN(text03_1),FIND(")+",text03_1,230))
Name ________________NUM0321: IF(ISERROR(FIND(")+",text03_1,230)),LEN(text03_1),FIND(")+",text03_1,230))
Name ________________num033: IF(ISERROR(FIND(")+",text03_2,230)),LEN(text03_2),FIND(")+",text03_2,230))
Name ________________num1: IF(ISERROR(FIND(")+",_xleta.TEXT,230)),LEN(_xleta.TEXT),FIND(")+",_xleta.TEXT,230))
Name ________________num2: IF(ISERROR(FIND(")+",text_1,230)),LEN(text_1),FIND(")+",text_1,230))
Name ________________num3: IF(ISERROR(FIND(")+",text_2,230)),LEN(text_2),FIND(")+",text_2,230))
Name _______________num031: IF(ISERROR(FIND(")+",Text03,230)),LEN(Text03),FIND(")+",Text03,230))
Name _______________num032: IF(ISERROR(FIND(")+",text03_1,230)),LEN(text03_1),FIND(")+",text03_1,230))
Name _______________num033: IF(ISERROR(FIND(")+",text03_2,230)),LEN(text03_2),FIND(")+",text03_2,230))
Name _______________num1: IF(ISERROR(FIND(")+",_xleta.TEXT,230)),LEN(_xleta.TEXT),FIND(")+",_xleta.TEXT,230))
Name _______________num2: IF(ISERROR(FIND(")+",text_1,230)),LEN(text_1),FIND(")+",text_1,230))
Name _______________num3: IF(ISERROR(FIND(")+",text_2,230)),LEN(text_2),FIND(")+",text_2,230))
Name ______________num031: IF(ISERROR(FIND(")+",Text03,230)),LEN(Text03),FIND(")+",Text03,230))
Name ______________num032: IF(ISERROR(FIND(")+",text03_1,230)),LEN(text03_1),FIND(")+",text03_1,230))
Name ______________num033: IF(ISERROR(FIND(")+",text03_2,230)),LEN(text03_2),FIND(")+",text03_2,230))
Name ______________num1: IF(ISERROR(FIND(")+",_xleta.TEXT,230)),LEN(_xleta.TEXT),FIND(")+",_xleta.TEXT,230))
Name ______________num2: IF(ISERROR(FIND(")+",text_1,230)),LEN(text_1),FIND(")+",text_1,230))
Name ______________num3: IF(ISERROR(FIND(")+",text_2,230)),LEN(text_2),FIND(")+",text_2,230))
Name _____________num031: IF(ISERROR(FIND(")+",Text03,230)),LEN(Text03),FIND(")+",Text03,230))
Name _____________num032: IF(ISERROR(FIND(")+",text03_1,230)),LEN(text03_1),FIND(")+",text03_1,230))
Name _____________NUM0321: IF(ISERROR(FIND(")+",text03_1,230)),LEN(text03_1),FIND(")+",text03_1,230))
Name _____________num033: IF(ISERROR(FIND(")+",text03_2,230)),LEN(text03_2),FIND(")+",text03_2,230))
Name _____________num1: IF(ISERROR(FIND(")+",_xleta.TEXT,230)),LEN(_xleta.TEXT),FIND(")+",_xleta.TEXT,230))
Name _____________num2: IF(ISERROR(FIND(")+",text_1,230)),LEN(text_1),FIND(")+",text_1,230))
Name _____________num3: IF(ISERROR(FIND(")+",text_2,230)),LEN(text_2),FIND(")+",text_2,230))
Name ____________num031: IF(ISERROR(FIND(")+",Text03,230)),LEN(Text03),FIND(")+",Text03,230))
Name ____________num032: IF(ISERROR(FIND(")+",text03_1,230)),LEN(text03_1),FIND(")+",text03_1,230))
Name ____________NUM0321: IF(ISERROR(FIND(")+",text03_1,230)),LEN(text03_1),FIND(")+",text03_1,230))
Name ____________num033: IF(ISERROR(FIND(")+",text03_2,230)),LEN(text03_2),FIND(")+",text03_2,230))
Name ____________num1: IF(ISERROR(FIND(")+",_xleta.TEXT,230)),LEN(_xleta.TEXT),FIND(")+",_xleta.TEXT,230))
Name ____________num2: IF(ISERROR(FIND(")+",text_1,230)),LEN(text_1),FIND(")+",text_1,230))
Name ____________num3: IF(ISERROR(FIND(")+",text_2,230)),LEN(text_2),FIND(")+",text_2,230))
Name ___________num031: IF(ISERROR(FIND(")+",Text03,230)),LEN(Text03),FIND(")+",Text03,230))
Name ___________num032: IF(ISERROR(FIND(")+",[1]!text03_1,230)),LEN([1]!text03_1),FIND(")+",[1]!text03_1,230))
Name ___________NUM0321: IF(ISERROR(FIND(")+",[1]!text03_1,230)),LEN([1]!text03_1),FIND(")+",[1]!text03_1,230))
Name ___________num033: IF(ISERROR(FIND(")+",[1]!text03_2,230)),LEN([1]!text03_2),FIND(")+",[1]!text03_2,230))
Name ___________num1: IF(ISERROR(FIND(")+",_xleta.TEXT,230)),LEN(_xleta.TEXT),FIND(")+",_xleta.TEXT,230))
Name ___________num2: IF(ISERROR(FIND(")+",[1]!text_1,230)),LEN([1]!text_1),FIND(")+",[1]!text_1,230))
Name ___________num3: IF(ISERROR(FIND(")+",[1]!text_2,230)),LEN([1]!text_2),FIND(")+",[1]!text_2,230))
Name __________num031: IF(ISERROR(FIND(")+",Text03,230)),LEN(Text03),FIND(")+",Text03,230))
Name __________num032: IF(ISERROR(FIND(")+",[1]!text03_1,230)),LEN([1]!text03_1),FIND(")+",[1]!text03_1,230))
Name __________NUM0321: IF(ISERROR(FIND(")+",[1]!text03_1,230)),LEN([1]!text03_1),FIND(")+",[1]!text03_1,230))
Name __________num033: IF(ISERROR(FIND(")+",[1]!text03_2,230)),LEN([1]!text03_2),FIND(")+",[1]!text03_2,230))
Name __________num1: IF(ISERROR(FIND(")+",_xleta.TEXT,230)),LEN(_xleta.TEXT),FIND(")+",_xleta.TEXT,230))
Name __________num2: IF(ISERROR(FIND(")+",[1]!text_1,230)),LEN([1]!text_1),FIND(")+",[1]!text_1,230))
Name __________num3: IF(ISERROR(FIND(")+",[1]!text_2,230)),LEN([1]!text_2),FIND(")+",[1]!text_2,230))

Sheet Cover
A2: CHN, Shanghai Campus Building 1 RF Project
A3: Build General Contractor Works
A4: Issue Date:
A6: Name of Tenderer:__________________________________
A8: 1 | B8: The direct subcontract packages (contractual parties: Microsoft and vendor): | D8: IT/ AV/ Security (GC to complete conduit work); System furniture & loose furniture.
A9: 2 | B9: Items are Included in Main Contract scope of works | D9: Listed as below:
D10: Construction
D11: Electrical/ Plumbing & drainage works
D12: Air-conditioning
D13: Fire Services
A14: 3 | B14: Material Request | D14: SOR should based on "FF&E and Internal Finishes Schedule"
A15: 4 | B15: Material Sample Board | D15: Bidders are to submitt material board for review and approval
A16: 5 | B16: The following descriptions is not to be changed, otherwise, your proposal will not be considered. All the items should be quoted. "0.00" price should be noted with "included" or "not provided", otherwise it will be interpreted as Included, no additional cost will be approved in future. Any new item should be put under the "other" category:
A17: 6 | B17: All item listed is for reference ONLY. Bidder(s) are responsible to validate the quantities in the BOQ and RFP and provide lump sum quotation with comprehensive reflection of the site conditions and the whole work scope. The contract will be a lump sum contract.

Sheet Summary
B1: Cost Summary
B3: Construction Area (Sqft) | C3: 38351.813
B4: Construction Area (Sqm) | C4: =C3*0.09290304 -> 3563
C8: PER Budget | D8: QS Estimation | E8: Vendor - A | F8: Vendor - B | G8: Vendor - C | H8: Vendor - D | I8: Vendor - E | J8: Historical
B9: Total Cost (USD) | C9: ='PER Budget'!B21 -> 10087575 | D9: ='QS Estimation'!B21 -> 10614203 | E9: ='Vendor Quotation'!C41 -> 10922446 | F9: ='Vendor Quotation'!D41 -> 11193181 | G9: ='Vendor Quotation'!E41 -> 10177153 | H9: ='Vendor Quotation'!F41 -> 11261479 | I9: ='Vendor Quotation'!G41 -> 11627647
B10: Unit Cost (USD/Sqm) | C10: =IFERROR(C9/$C$4,0) -> 2831.2027 | D10: =IFERROR(D9/$C$4,0) -> 2979.0072 | E10: =IFERROR(E9/$C$4,0) -> 3065.5194 | F10: =IFERROR(F9/$C$4,0) -> 3141.5046 | G10: =IFERROR(G9/$C$4,0) -> 2856.3439 | H10: =IFERROR(H9/$C$4,0) -> 3160.6733 | I10: =IFERROR(I9/$C$4,0) -> 3263.4429 | J10: ='[39]Historical Unit Rates'!B22 -> 2500
D11: =E13 -> 0 | E11: =E9/C9 -> 1.0827623 | F11: =F9/D9 -> 1.0545475 | G11: =G9/E9 -> 0.93176506 | H11: =H9/F9 -> 1.0061018 | I11: =I9/G9 -> 1.1425245

Sheet OUTPUT
A1: VISUALS
A2: Page1 | C2: Page2 | E2: Page3
A3: Executive Recommendation Card Cost Variance (Vendor Total Price vs. PER-Budget) | C3: Executive Decision Dashboard Cost Variance (Vendor Category Cost vs. QS Estimate ) | E3: Executive Decision Dashboard Cost Variance (Vendor Unit Price vs. Historical Unit Price )
A4: Vendor | B4: Approval Within PER(±10%) | C4: #VALUE! | D4: Variance ± 5% - Reasonable | E4: #VALUE! | F4: Variance ± 5% - Reasonable
B5: Approval with condition（±10%＜Variance≤±20%） Recommended Value/Potential Savings | D5: ±5%＜Variance≤±15% – Review required | F5: ±5%＜Variance≤±15% – Review required
B6: Reject(Variance＞±20%) | D6: Variance＞±15% – Significant cost concern | F6: Variance＞±15% – Significant cost concern

Sheet Introduction
A1: Bill of Quantity Introduction
A3: The BOQ is applied for CHN, Shanghai Campus Building 1 RF Project.
A5: 1 | B5: All Chinese and English descriptions are mainly in Chinese.
B6: 所有的中英文描述均以中文为主。
A8: 2 | B8: The descriptions given herein are not intended as complete descriptions of the items, but merely as indication of their extent. All details of the various items are as shown on the Drawings and described in the Specification.
B9: 附表中对各项目之说明并非作为各项目之完整说明，而概括地表示其范围。各项目之所有细则须按照工料规范及招标图纸所述的执行。
A11: 3 | B11: The Contractor's rates for the items contained in this Schedule of Rates shall be deemed to include cost of all incidentals of labor, material, plant (working or idle), supervision, general attendance, profit and all other things and matters etc. This rates shall be used for the purpose of assessing variations.
B12: 附表中各项目单价应包括人工、物料及损耗、机械、监督管理、现场、利润及一切按照合同及技术规范要求按时及令发包方满意的完成本工程不可或缺的一切有关的附件及费用等。填报的单价将被作为日后变更评估的依据。
A14: 4 | B14: All item listed is for reference ONLY. Bidder(s) are responsible to validate the quantities in the BOQ and RFP and provide lump sum quotation with comprehensive reflection of the site conditions and the whole work scope.
B15: BOQ中所有列项及参考数量仅供参考。投标单位需自行核实BOQ的数量和RFP，并提供综合反映现场条件和整个工作范围的总价报价。
A17: 5 | B17: The prices inserted by the Contractor are "lump sum" prices and will not be adjusted for any errors in the Contractor's measurement and pricing.
B18: 投标单位的投标总价为包干价，不会因投标单位的任何量度或报价计算错误而调整。
A20: 6 | B20: The Contractor shall be fully responsible for the accuracy of the quantities set out in the Schedule of Quantities and Rates on which his Tender has been based. The Contract Sum and rates will not be adjusted, except for the mechanism set out in the tender documents for the frame contracts.
B21: 对于单价表内之数量及单价，其准确与否的风险归承包单位；除招标文件中为框架合同约定的调价机制外，本合同总价及单价维持不变。
A23: 7 | B23: The Employer shall not be responsible for any omissions and errors in the description of items. The onus shall be on the Contractor to check the Tender Documents in details for any omissions and errors. Should such omissions and errors be discovered at any time, they shall be deemed to have been included in the prices of the relevant items.
B24: 发包方不会对本附表中的任何项目的缺失或项目描述的错误负责。投标单位须自行检查及复核，任何时候发现有上述缺失或错误，有关费用将被视为已包括于其他相关项目费用中。
A26: 8 | B26: Whenever the word "Allow" occurs in this Schedule of Rates, the cost of the items shall be at the risk of the Contractor and no adjustment will be made at the settlement of accounts. In the absence of any price against such items, the cost shall be deemed to be included in the rates of the other items.
B27: 附表中以“项”计的项目之价款为包干价，其准确与否的风险归承包单位，不论此等项目实际发生的费用与投标单位之估计有多大出入，亦不论有无设计变更，此等费用均不作调整。除非在不需要时，整项扣除。任何项目若没有填上价款的，其所需费用视作已包括在其他项目的价款或工程单价内。
A29: 9 | B29: The price of "Allow for other works not listed above" are deemed to include for all those works which are not listed in the Schedule of Rates but are required by the Contract according to the Drawings and Specification. The onus shall be on the Contractor to check for such works and price them in this item. If no price is inserted here, the costs are deemed to have been spread over the other items proportionately.
B30: “未列但图纸和/或规范和/或现场所需要之工作”为单价表内未列明但按招标图纸及技术规范要求所需之项目。投标单位需根据招标图纸及技术规范要求自行检查及填报此等项目。如投标单位未对此项目报价，则有关费用视作已包括在其他项目的价款或工程单价内。
A32: 10 | B32: The unit rates are to include for all the necessary testing and commissioning, cleaning includes all the materials, instruments, tools, labor in connection therewith.
B33: 此外,单价亦应包括各必须安装及测试、调核、试运行、清洁的材料、工具及工资(包括节假日，夜班及赶工费用)等费用。

Sheet Rules of measurement
A1: Measurement/pricing rules 计量/计价规则
A3: 1.0 General 总则
B5: 1.1 basic rules 基本规则
C7: 1.1.1 Purpose 目的
D8: "The purpose of this "Rules for Calculation of Quantities" is to provide a uniform unit of calculation and a standardized method of measurement for the calculation of quantities in the "Table of Unit Prices of Works", so that the offeror can calculate the quantities of the works and prepare accurate and feasible quotations on the basis of the uniformity. All quantities must be calculated in accordance with these rules, regardless of whether the quantities are provided by the Owner as "tentative quantities" or the quantities are calculated by the Offeror. The "Unit Price Statement" describes and defines the nature and content of all billable items in the quantity calculation rules. Each item in the unit price list must be bid in accordance with the requirements and bases of the "Unit Price Statement" and the "Rules for Calculation of Quantities"." 本“工程量计算规则”的目的是为计算“工程单价表”内的数量而提供统一的计算单位和标准的工程计量方法，以便报价人能在统一的基础下自算工程量及编制准确可行的报价。不论是由业主方提供之“暂定数量”项目的工程量，或由报价人自算的工程量，所有工程量必须按照本计算规则来计算。 “单价说明”是针对工程量计算规则中所有计费项目的性质与内容给予描述与定义。工程单价表中各项目必须根据“单价说明”及“工程量计算规则”的要求与依据来投价。
C10: 1.1.2 unit of measure 计量单位
D11: The following units of measure shall be used consistently, unless otherwise indicated later: 除后面另有说明外，须一致采用以下计量单位：
D12: (i) Items measured in volume - cubic meters (m3) 以体积为单位之项目－立方米（m3）
D13: (ii) Items in terms of area - square meters (sm) 以面积为单位之项目－平方米（sm）
D14: (iii) Items in length - meters (lm) 以长度为单位之项目－米（lm）
D15: (v) Item in pieces - quantity (nos.) 以件为单位之项目－数量（nos.）
D16: (vi) item of work measured in aggregate - item (sum) 综合计量某项工作－项（sum）
C18: 1.1.3 Unit accuracy of inventory preparation 编制清单的单位精度
D19: (1) In case of change or addition or deletion of items, increase or deletion of item quantities shall be calculated to the extent of 0.01 meter, 0.01 square meter, and 0.01 cubic meter. 在项目变更或增减时，项目工程量之增减须计算至0.01米、0.01平米、0.01立米。
D20: (2) Dimensions not stated in units in the list description are in millimeters. 在清单说明中未注明单位的尺寸均为毫米。
C22: 1.1.4 Net value 净值
D23: (1) Unless otherwise stated, all items are calculated on a net basis after installation in place, and any wear and tear needs to be taken into account in the composite unit price 除另有说明外，所有项目均以安装就位后的净值计算，任何损耗需要考虑在综合单价中
C25: 1.1.5 Costs included in the unit price 项目已包括的费用
D26: Unless otherwise indicated, the unit price or price for each item shall have included, but not be limited to, the following:
D27: (1) Labor and all related costs.
D28: (2) Materials, goods, and all related costs (e.g., transportation, delivery, unloading, storage, return of packing materials, handling, hoisting, and lowering).
D29: (3) In-situ assembly and installation of materials and goods.
D30: (4) Use of construction machinery.
D31: (5) All cutting and wastage.
D32: (6) Direct costs, risks and charges.
D33: (7) All costs required by the government and related agencies/departments.
D34: (8) Detailed drawings required for the construction and installation of the work.
D35: (9) Cost of consumable materials and appliances used.
D36: (10) Difference in cost between large-scale construction and small-scale construction.
D37: (11) The cost of liaison and coordination with other contractors, owners, architects, governmental agencies, etc. necessary for the construction.
... D55: （14）平面或立面呈弧型的额外工作费用
C57: 1.1.6
D58: Unless otherwise stated, the unit prices or rates in the schedule of unit prices are applicable to design and construction under all circumstances (i.e., including changes in depth, construction program, site conditions, varying soil quality, underground obstructions, etc.). Therefore, regardless of the circumstances under which the work is designed and constructed, the unit prices or rates in the schedule of unit prices will be the basis for pricing and will not be subject to additional adjustments. 除另有说明外，工程单价表内的单价或价款适用于所有情形下设计并施工（即包括深度变化、施工方案、现场情况、不同土质、地下障碍物等）。所以，不论任何情况下设计并施工，工程单价表内的单价或价款将成为计价的根据，并不会另外作出调整。
B60: 1.2 specialized term 专用术语
C61: 1.2.1 item“项”
D62: When the word "item" appears in the unit of quantity in the description of the item in the unit price list, the cost of the item is at the risk of the contractor and will not be adjusted at the final account, and if such an item is not quoted, the cost is deemed to have been included in other unit prices/price in the unit price list. If the item has never occurred, the amount of the item reported in the unit price list will be deducted from the final account. 当工程单价表项目说明的数量单位中出现“项”字样，则该项目的造价由承包单位承担风险，决算时不作调整，若此类项目没有报价，造价即视为已包括在工程单价表之其它单价/价款中。如该项目从来没有发生过，则决算时将把填报在单价表内的项目金额全部扣除。
C64: 1.2.2 Adjustments to the "provisional price" of materials 材料“暂定价款”的调整
D65: If the item description of the unit price list of the project appears in the "temporary price of materials", the "temporary price of materials" is only the price of materials delivered to the construction site for the project, the unit price of the project reported by the Contractor in addition to the "temporary price of materials" itself should be included. The unit price quoted by the Contractor for the project shall include, in addition to the price of the "tentative price of materials" itself, the costs of wear and tear, handling, installation, fees, and all other similar materials and operations such as cement, mortar, and other auxiliary materials required. 若工程单价表之项目说明中出现“材料暂定价款”，此“材料暂定价款”只为该项目材料交付到施工现场之价格，承包单位所投报该项目之单价除应包括“材料暂定价款”本身的价额外，还需包括损耗、装卸、安装、规费及所需要的辅助材料如水泥、砂浆等所有其它类似材料和作业的费用。
D67: The contract unit price will be adjusted by the net difference between the specified "provisional price of materials" and the "actual price of supply" and the actual cost will be calculated on the basis of the net value of the quantity of work involved in the construction of the project. 该合同单价将按指定的“材料暂定价款”及“实际供应价”之净差调整，并依据建造该项目工程量之净值来计算实际造价。
C69: 1.2.3 "Provisional number"“暂定数量”
...

Sheet PER Budget
A1: PER Category | B1: Budget Amount (USD)
A2: Partitions (Drywall, Glazing etc.) | B2: 1185018.7
A3: Flooring Works (Fit-Out) | B3: 365437.82
A4: Joinery Works | B4: 790620.55
A5: Signage / Graphics | B5: 86030.488
A6: Carpet | B6: 418220.66
A7: Miscellaneous Items Works (Fit-Out Works) | B7: 1202460.9
A8: Fire Suppression Systems (Fit-Out Works) | B8: 539336.75
A9: Building Management Systems | B9: 182203.34
A10: Low Side Electrical Works | B10: 751300.1
A11: HVAC systems | B11: 1923047.7
A12: Dry Works & Wall Cladding | B12: 590870.66
A13: Ceiling (Fit Out) | B13: 733910.16
... A21: TOTAL | B21: 10087575

Sheet QS Estimation
A2: QS Estimate Category | B2: Total Amount (USD)
A3: Partitions (Drywall, Glazing etc.) | B3: 1260943.5
A4: HVAC systems | B4: 1993235
A5: Miscellaneous Items Works (Fit-Out Works) | B5: 1293264.6
A6: Ceiling (Fit Out) | B6: 776799.38
A7: Light Fixtures | B7: 628513.01
A8: Dry Works & Wall Cladding | B8: 625400.74
A9: Joinery Works | B9: 836823.89
A10: Low Side Electrical Works | B10: 782777.74
A11: Carpet | B11: 440330.88
A12: Flooring Works (Fit-Out) | B12: 384757.55
A13: Uninterruptible Power Supply (UPS) Works | B13: 12907.583
A14: Sprinkler Installations (Fit-Out Works) | B14: 231243.96
... A21: TOTAL CLASSIFIED | B21: 10614203

Sheet Vendor Quotation
A2: =Cover!A2 -> CHN, Shanghai Campus Building 1 RF Project
A3: =Cover!A3 -> Build General Contractor Works
A4: =Cover!A4 -> Issue Date:
A6: =Cover!A6 -> Name of Tenderer:__________________________________
A8: SUMMARY PAGE
C9: Vendor-A | D9: Vendor-B | E9: Vendor-C | F9: Vendor-D | G9: Vendor-E
A10: No. | B10: DESCRIPTION | C10: GC Total (USD) | D10: GC Total (USD) | E10: GC Total (USD) | F10: GC Total (USD) | G10: GC Total (USD)
B11: Preliminaries (inclusive of M&E Works)
A12: A | B12: Preliminaries (inclusive of M&E Works) | C12: 546846.37 | D12: 993728.83 | E12: 736323.59 | F12: 438585.14 | G12: 576012.57
B14: Fit out works 装饰工程
A15: B | B15: Demolition Works 拆除工程 | C15: 119849.1 | D15: 233860.7 | E15: 221826.44 | F15: 96871.504 | G15: 156184.22
A16: C | B16: Partition Works 隔墙工程 | C16: 849635.18 | D16: 821501.05 | E16: 1106511 | F16: 703315.33 | G16: 846904.06
A17: D | B17: Wall finish 墙面饰面 | C17: 417919.18 | D17: 602425.32 | E17: 445403.16 | F17: 690771.49 | G17: 555063.02
A18: E | B18: Ceiling Works 天花工程 | C18: 715053.73 | D18: 535674.71 | E18: 812038.92 | F18: 801011.75 | G18: 564639.68
A19: G | B19: Flooring Works (Fit-Out) 地面工程 | C19: 477632.44 | D19: 507127.22 | E19: 391893.22 | F19: 614742.41 | G19: 457736.03
A20: H | B20: Carpet 地毯工程 | C20: 625465.15 | D20: 461285.82 | E20: 445217.92 | F20: 885170.58 | G20: 429503.45
A21: I | B21: Door Works 门工程 | C21: 434751.24 | D21: 495751.05 | E21: 423645.21 | F21: 364999.16 | G21: 518448.87
A22: J | B22: Carpentry Works 木器工程 | C22: 375383.69 | D22: 307515.49 | E22: 254766.95 | F22: 239009.72 | G22: 144286.51
A23: K | B23: Internal Staircase 内部楼梯 | C23: 48233.678 | D23: 65832.754 | E23: 32710.704 | F23: 42976.893 | G23: 67681.166
A24: L | B24: Atrium works 中庭工程 | C24: 58127.264 | D24: 152019.42 | E24: 94501.447 | F24: 131542.08 | G24: 229863.88
A25: M | B25: Signage / Graphics 标识及图形 | C25: 36548.736 | D25: 17865.086 | E25: 96946.236 | F25: 13121.478 | G25: 20981.832
A26: N | B26: Blinds 窗帘 | C26: 62936.923 | D26: 44408.772 | E26: 160250.79 | F26: 21624.045 | G26: 36696.613
A27: O | B27: Miscellaneous Items Works 其他杂项 | C27: 378108.89 | D27: 190134.78 | E27: 118922.77 | F27: 131082.57 | G27: 149716.47
B29: MEP works 机电工程
A30: P | B30: Building Management Systems (BMS) | C30: 275672.88 | D30: 316095.32 | E30: 197395.69 | F30: 244799.37 | G30: 376965.88
A31: Q | B31: Low Side Electrical Works 低压电气 | C31: 1016195.7 | D31: 756933.66 | E31: 684190.8 | F31: 917038.8 | G31: 900709.43
A32: R | B32: Uninterruptible Power Supply (UPS) Works | C32: 25926.455 | D32: 22732.436 | E32: 15394.362 | F32: 22956.104 | G32: 26618.419
A33: S | B33: Light Fixtures 灯具 | C33: 949513.87 | D33: 958438.27 | E33: 556923.08 | F33: 854709.37 | G33: 927659.28
A34: T | B34: Lighting Management System 灯控系统 | C34: 417224.46 | D34: 296517.32 | E34: 242001.88 | F34: 381124.44 | G34: 412102.85
A35: U | B35: Air-conditioning Works 空调工程 | C35: 1996643.3 | D35: 2154309.9 | E35: 2055253.5 | F35: 2061141.9 | G35: 3061031
A36: V | B36: Fire Suppression Systems (Fit-Out Works) | C36: 198793.38 | D36: 298165.46 | E36: 507188.19 | F36: 352178.62 | G36: 222602.87
A37: W | B37: Sprinkler Installations (Fit-Out Works) | C37: 301032.6 | D37: 289370.52 | E37: 203774.63 | F37: 505131.24 | G37: 329130.74
A38: X | B38: Fire Suppression Systems 消防系统 | C38: 523126.85 | D38: 522838.19 | E38: 259842.41 | F38: 631662.65 | G38: 484655.71
A39: Y | B39: Plumbing & Drainage works 给排水系统 | C39: 71824.69 | D39: 148648.84 | E39: 114230.4 | F39: 115912.3 | G39: 132452.53
B41: Total | C41: 10922446 | D41: 11193181 | E41: 10177153 | F41: 11261479 | G41: 11627647

Sheet MAPPING RULES
A1: Vendor WBS Description | B1: PER-Budget / QS Estimate Category
A2: Preliminaries (inclusive of M&E Works) | B2: Miscellaneous Items Works (Fit-Out Works)
A3: Demolition Works 拆除工程 | B3: Miscellaneous Items Works (Fit-Out Works)
A4: Partition Works 隔墙工程 | B4: Partitions (Drywall, Glazing etc.)
A5: Wall finish 墙面饰面 | B5: Dry Works & Wall Cladding
A6: Ceiling Works 天花工程 | B6: Ceiling (Fit Out)
A7: Flooring Works (Fit-Out) 地面工程 | B7: Flooring Works (Fit-Out)
A8: Carpet 地毯工程 | B8: Carpet
A9: Door Works 门工程 | B9: Joinery Works
A10: Carpentry Works 木器工程 | B10: Joinery Works
A11: Internal Staircase 内部楼梯 | B11: Joinery Works
A12: Atrium works 中庭工程 | B12: Dry Works & Wall Cladding
... A25: Plumbing & Drainage works 给排水系统 | B25: Public Health Engineering (PHE) Works

Sheet Historical Unit Rates
A2: QS Category | B2: Historical Unit Rate (USD/Sqm)
A3: Partitions (Drywall, Glazing etc.) | B3: 295.20901
A4: HVAC systems | B4: 475.84638
A5: Miscellaneous Items Works (Fit-Out Works) | B5: 300.68782
A6: Ceiling (Fit Out) | B6: 184.19163
A7: Light Fixtures | B7: 143.81158
A8: Dry Works & Wall Cladding | B8: 150.31213
A9: Joinery Works | B9: 195.33609
A10: Low Side Electrical Works | B10: 185.24809
A11: Carpet | B11: 103.39388
A12: Flooring Works (Fit-Out) | B12: 89.279768
A13: Uninterruptible Power Supply (UPS) Works | B13: 3.0665502
A14: Sprinkler Installations (Fit-Out Works) | B14: 56.271796
... A22: Weighted Average Unit Rate | B22: 2500

Sheet HYE新增项
A2: Bill of Quantity for Build General Contractor Works
A3: =[40]Summary!A2 -> CHN, Shanghai Campus Building 1 RF Project
A4: =[40]Summary!A4 -> Issue Date: 2026/08/04
A6: =[40]Summary!A6 -> Name of Tenderer:___HYE_________________________________
A8: DO NOT change the form of this Schdule of Rates, any changes or ideas please use "Please specify" rows 不要自行更改或修改表格格式，任何改动需使用”请列明“行
A10: No. 序号 | B10: DESCRIPTION OF WORKS 描述 | C10: Material Code 材料编号 | D10: Spec.Brand 品牌型号 | E10: Refer. Quantity/参考数量 | T10: Tender Quantity/ 投标数量 | AI10: Unit 单位 | AJ10: Unit Rate(¥) 单价 | AM10: Total(RMB)/ 合计 | AU10: Total(RMB)/ 合计 | BB10: Remarks 备注
E11: Phase 1 短翼 | M11: Phase 2 长翼 | T11: Phase 1 短翼 | AB11: Phase 2 长翼 | AJ11: Labor | AK11: Material | AL11: Total | AM11: Phase 1 短翼 | AU11: Phase 2 长翼
E12: -1F | F12: 1F | G12: 2F | H12: 3F | I12: 4F | J12: 5F | K12: Roof | L12: Total | M12: 1F | N12: 2F | O12: 3F | P12: 4F | Q12: 5F | R12: Roof | S12: Total | T12: -1F | U12: 1F | V12: 2F | W12: 3F | X12: 4F | Y12: 5F | Z12: Roof | AA12: Total | AB12: 1F | AC12: 2F | AD12: 3F | AE12: 4F | AF12: 5F | AG12: Roof | AH12: Total | AJ12: 人工 | AK12: 材料 | AL12: 小计 | AM12: -1F | AN12: 1F | AO12: 2F | AP12: 3F | AQ12: 4F | AR12: 5F | AS12: Roof | AT12: Total | AU12: 1F | AV12: 2F | AW12: 3F | AX12: 4F | AY12: 5F | AZ12: Roof | BA12: Total
A13: L | B13: Electrical Works 强电工程
A14: 1 | B14: 提供安装配电箱 RAPRBH4 | Z14: 1 | AA14: =SUM(T14:Z14) -> 1 | AH14: =SUM(AB14:AG14) -> 0 | AI14: set | AJ14: 950 | AK14: 11400 | AL14: =AJ14+AK14 -> 12350 | AM14: =T14*AL14 -> 0 | AN14: =U14*AL14 -> 0 | AO14: =V14*AL14 -> 0 | AP14: =W14*AL14 -> 0 | AQ14: =X14*AL14 -> 0 | AR14: =Y14*AL14 -> 0 | AS14: =Z14*AL14 -> 12350 | AT14: =SUM(AM14:AS14) -> 12350 | AU14: =AB14*AL14 -> 0 | AV14: =AC14*AL14 -> 0 | AW14: =AD14*AL14 -> 0 | AX14: =AE14*AL14 -> 0 | AY14: =AF14*AL14 -> 0 | AZ14: =AG14*AL14 -> 0 | BA14: =SUM(AU14:AZ14) -> 0
A15: 2 | B15: 配电箱改造 1AP2-1 | U15: 1 | AA15: =SUM(T15:Z15) -> 1 | AH15: =SUM(AB15:AG15) -> 0 | AI15: set | AJ15: 1100 | AK15: 600 | AL15: =AJ15+AK15 -> 1700 | AM15: =T15*AL15 -> 0 | AN15: =U15*AL15 -> 1700 | AO15: =V15*AL15 -> 0 | AP15: =W15*AL15 -> 0 | AQ15: =X15*AL15 -> 0 | AR15: =Y15*AL15 -> 0 | AS15: =Z15*AL15 -> 0 | AT15: =SUM(AM15:AS15) -> 1700 | AU15: =AB15*AL15 -> 0 | AV15: =AC15*AL15 -> 0 | AW15: =AD15*AL15 -> 0 | AX15: =AE15*AL15 -> 0 | AY15: =AF15*AL15 -> 0 | AZ15: =AG15*AL15 -> 0 | BA15: =SUM(AU15:AZ15) -> 0
A16: 3 | B16: 配电箱改造 2ATit1 | V16: 1 | AA16: =SUM(T16:Z16) -> 1 | AH16: =SUM(AB16:AG16) -> 0 | AI16: set | AJ16: 1100 | AK16: 600 | AL16: =AJ16+AK16 -> 1700 | AM16: =T16*AL16 -> 0 | AN16: =U16*AL16 -> 0 | AO16: =V16*AL16 -> 1700 | AP16: =W16*AL16 -> 0 | AQ16: =X16*AL16 -> 0 | AR16: =Y16*AL16 -> 0 | AS16: =Z16*AL16 -> 0 | AT16: =SUM(AM16:AS16) -> 1700 | AU16: =AB16*AL16 -> 0 | AV16: =AC16*AL16 -> 0 | AW16: =AD16*AL16 -> 0 | AX16: =AE16*AL16 -> 0 | AY16: =AF16*AL16 -> 0 | AZ16: =AG16*AL16 -> 0 | BA16: =SUM(AU16:AZ16) -> 0
A17: 4 | B17: 配电箱改造 UPS31-1 | U17: 1 | AA17: =SUM(T17:Z17) -> 1 | AH17: =SUM(AB17:AG17) -> 0 | AI17: set | AJ17: 1100 | AK17: 2400 | AL17: =AJ17+AK17 -> 3500 | AM17: =T17*AL17 -> 0 | AN17: =U17*AL17 -> 3500 | AO17: =V17*AL17 -> 0 | AP17: =W17*AL17 -> 0 | AQ17: =X17*AL17 -> 0 | AR17: =Y17*AL17 -> 0 | AS17: =Z17*AL17 -> 0 | AT17: =SUM(AM17:AS17) -> 3500 | AU17: =AB17*AL17 -> 0 | AV17: =AC17*AL17 -> 0 | AW17: =AD17*AL17 -> 0 | AX17: =AE17*AL17 -> 0 | AY17: =AF17*AL17 -> 0 | AZ17: =AG17*AL17 -> 0 | BA17: =SUM(AU17:AZ17) -> 0
A18: 5 | B18: 配电箱改造 UPS51-1 | U18: 1 | AA18: =SUM(T18:Z18) -> 1 | AH18: =SUM(AB18:AG18) -> 0 | AI18: set | AJ18: 1100 | AK18: 2400 | AL18: =AJ18+AK18 -> 3500 | AM18: =T18*AL18 -> 0 | AN18: =U18*AL18 -> 3500 | AO18: =V18*AL18 -> 0 | AP18: =W18*AL18 -> 0 | AQ18: =X18*AL18 -> 0 | AR18: =Y18*AL18 -> 0 | AS18: =Z18*AL18 -> 0 | AT18: =SUM(AM18:AS18) -> 3500 | AU18: =AB18*AL18 -> 0 | AV18: =AC18*AL18 -> 0 | AW18: =AD18*AL18 -> 0 | AX18: =AE18*AL18 -> 0 | AY18: =AF18*AL18 -> 0 | AZ18: =AG18*AL18 -> 0 | BA18: =SUM(AU18:AZ18) -> 0
A19: 6 | B19: 模块式风冷热泵隔离开关箱 | Z19: 18 | AA19: =SUM(T19:Z19) -> 18 | AH19: =SUM(AB19:AG19) -> 0 | AI19: set | AJ19: 1100 | AK19: 10200 | AL19: =AJ19+AK19 -> 11300 | AM19: =T19*AL19 -> 0 | AN19: =U19*AL19 -> 0 | AO19: =V19*AL19 -> 0 | AP19: =W19*AL19 -> 0 | AQ19: =X19*AL19 -> 0 | AR19: =Y19*AL19 -> 0 | AS19: =Z19*AL19 -> 203400 | AT19: =SUM(AM19:AS19) -> 203400 | AU19: =AB19*AL19 -> 0 | AV19: =AC19*AL19 -> 0 | AW19: =AD19*AL19 -> 0 | AX19: =AE19*AL19 -> 0 | AY19: =AF19*AL19 -> 0 | AZ19: =AG19*AL19 -> 0 | BA19: =SUM(AU19:AZ19) -> 0
A20: 7 | B20: WDZB-YJY-4x120+1x95 | Z20: 1680 | AA20: =SUM(T20:Z20) -> 1680 | AH20: =SUM(AB20:AG20) -> 0 | AI20: m | AJ20: 85 | AK20: 792 | AL20: =AJ20+AK20 -> 877 | AM20: =T20*AL20 -> 0 | AN20: =U20*AL20 -> 0 | AO20: =V20*AL20 -> 0 | AP20: =W20*AL20 -> 0 | AQ20: =X20*AL20 -> 0 | AR20: =Y20*AL20 -> 0 | AS20: =Z20*AL20 -> 1473360 | AT20: =SUM(AM20:AS20) -> 1473360 | AU20: =AB20*AL20 -> 0 | AV20: =AC20*AL20 -> 0 | AW20: =AD20*AL20 -> 0 | AX20: =AE20*AL20 -> 0 | AY20: =AF20*AL20 -> 0 | AZ20: =AG20*AL20 -> 0 | BA20: =SUM(AU20:AZ20) -> 0
A21: 8 | B21: WDZB-YJY-3x70 | Z21: 228 | AA21: =SUM(T21:Z21) -> 228 | AH21: =SUM(AB21:AG21) -> 0 | AI21: m | AJ21: 42 | AK21: 286 | AL21: =AJ21+AK21 -> 328 | AM21: =T21*AL21 -> 0 | AN21: =U21*AL21 -> 0 | AO21: =V21*AL21 -> 0 | AP21: =W21*AL21 -> 0 | AQ21: =X21*AL21 -> 0 | AR21: =Y21*AL21 -> 0 | AS21: =Z21*AL21 -> 74784 | AT21: =SUM(AM21:AS21) -> 74784 | AU21: =AB21*AL21 -> 0 | AV21: =AC21*AL21 -> 0 | AW21: =AD21*AL21 -> 0 | AX21: =AE21*AL21 -> 0 | AY21: =AF21*AL21 -> 0 | AZ21: =AG21*AL21 -> 0 | BA21: =SUM(AU21:AZ21) -> 0
A22: 9 | B22: WDZB-YJY-3x16+1x16 | Z22: 62 | AA22: =SUM(T22:Z22) -> 62 | AH22: =SUM(AB22:AG22) -> 0 | AI22: m | AJ22: 24 | AK22: 90 | AL22: =AJ22+AK22 -> 114 | AM22: =T22*AL22 -> 0 | AN22: =U22*AL22 -> 0 | AO22: =V22*AL22 -> 0 | AP22: =W22*AL22 -> 0 | AQ22: =X22*AL22 -> 0 | AR22: =Y22*AL22 -> 0 | AS22: =Z22*AL22 -> 7068 | AT22: =SUM(AM22:AS22) -> 7068 | AU22: =AB22*AL22 -> 0 | AV22: =AC22*AL22 -> 0 | AW22: =AD22*AL22 -> 0 | AX22: =AE22*AL22 -> 0 | AY22: =AF22*AL22 -> 0 | AZ22: =AG22*AL22 -> 0 | BA22: =SUM(AU22:AZ22) -> 0
A23: 10 | B23: WDZB-YJY-3x10+1x10 | Z23: 22 | AA23: =SUM(T23:Z23) -> 22 | AH23: =SUM(AB23:AG23) -> 0 | AI23: m | AJ23: 19 | AK23: 57.4 | AL23: =AJ23+AK23 -> 76.4 | AM23: =T23*AL23 -> 0 | AN23: =U23*AL23 -> 0 | AO23: =V23*AL23 -> 0 | AP23: =W23*AL23 -> 0 | AQ23: =X23*AL23 -> 0 | AR23: =Y23*AL23 -> 0 | AS23: =Z23*AL23 -> 1680.8 | AT23: =SUM(AM23:AS23) -> 1680.8 | AU23: =AB23*AL23 -> 0 | AV23: =AC23*AL23 -> 0 | AW23: =AD23*AL23 -> 0 | AX23: =AE23*AL23 -> 0 | AY23: =AF23*AL23 -> 0 | AZ23: =AG23*AL23 -> 0 | BA23: =SUM(AU23:AZ23) -> 0
A24: 11 | B24: WDZB-YJY-3x6+1x6 | Z24: 40 | AA24: =SUM(T24:Z24) -> 40 | AH24: =SUM(AB24:AG24) -> 0 | AI24: m | AJ24: 12 | AK24: 35.5 | AL24: =AJ24+AK24 -> 47.5 | AM24: =T24*AL24 -> 0 | AN24: =U24*AL24 -> 0 | AO24: =V24*AL24 -> 0 | AP24: =W24*AL24 -> 0 | AQ24: =X24*AL24 -> 0 | AR24: =Y24*AL24 -> 0 | AS24: =Z24*AL24 -> 1900 | AT24: =SUM(AM24:AS24) -> 1900 | AU24: =AB24*AL24 -> 0 | AV24: =AC24*AL24 -> 0 | AW24: =AD24*AL24 -> 0 | AX24: =AE24*AL24 -> 0 | AY24: =AF24*AL24 -> 0 | AZ24: =AG24*AL24 -> 0 | BA24: =SUM(AU24:AZ24) -> 0
A25: 12 | B25: 提供及安装ISP1装饰吊灯 | U25: 5 | W25: 2 | AA25: =SUM(T25:Z25) -> 7 | AH25: =SUM(AB25:AG25) -> 0 | AI25: set | AJ25: 180 | AK25: 5400 | AL25: =AJ25+AK25 -> 5580 | AM25: =T25*AL25 -> 0 | AN25: =U25*AL25 -> 27900 | AO25: =V25*AL25 -> 0 | AP25: =W25*AL25 -> 11160 | AQ25: =X25*AL25 -> 0 | AR25: =Y25*AL25 -> 0 | AS25: =Z25*AL25 -> 0 | AT25: =SUM(AM25:AS25) -> 39060 | AU25: =AB25*AL25 -> 0 | AV25: =AC25*AL25 -> 0 | AW25: =AD25*AL25 -> 0 | AX25: =AE25*AL25 -> 0 | AY25: =AF25*AL25 -> 0 | AZ25: =AG25*AL25 -> 0 | BA25: =SUM(AU25:AZ25) -> 0
A26: 13 | B26: 提供及安装USB插座 | U26: 9 | V26: 6 | W26: 14 | X26: 8 | Y26: 11 | AA26: =SUM(T26:Z26) -> 48 | AB26: 15 | AC26: 21 | AD26: 21 | AE26: 22 | AF26: 12 | AH26: =SUM(AB26:AG26) -> 91 | AI26: set | AJ26: 110 | AK26: 160 | AL26: =AJ26+AK26 -> 270 | AM26: =T26*AL26 -> 0 | AN26: =U26*AL26 -> 2430 | AO26: =V26*AL26 -> 1620 | AP26: =W26*AL26 -> 3780 | AQ26: =X26*AL26 -> 2160 | AR26: =Y26*AL26 -> 2970 | AS26: =Z26*AL26 -> 0 | AT26: =SUM(AM26:AS26) -> 12960 | AU26: =AB26*AL26 -> 4050 | AV26: =AC26*AL26 -> 5670 | AW26: =AD26*AL26 -> 5670 | AX26: =AE26*AL26 -> 5940 | AY26: =AF26*AL26 -> 3240 | AZ26: =AG26*AL26 -> 0 | BA26: =SUM(AU26:AZ26) -> 24570
A27: 14 | B27: 提供及安装设备出线点位 | U27: 15 | V27: 18 | W27: 19 | X27: 19 | Y27: 23 | AA27: =SUM(T27:Z27) -> 94 | AB27: 27 | AC27: 27 | AD27: 30 | AE27: 29 | AF27: 21 | AH27: =SUM(AB27:AG27) -> 134 | AI27: set | AJ27: 180 | AK27: 180 | AL27: =AJ27+AK27 -> 360 | AM27: =T27*AL27 -> 0 | AN27: =U27*AL27 -> 5400 | AO27: =V27*AL27 -> 6480 | AP27: =W27*AL27 -> 6840 | AQ27: =X27*AL27 -> 6840 | AR27: =Y27*AL27 -> 8280 | AS27: =Z27*AL27 -> 0 | AT27: =SUM(AM27:AS27) -> 33840 | AU27: =AB27*AL27 -> 9720 | AV27: =AC27*AL27 -> 9720 | AW27: =AD27*AL27 -> 10800 | AX27: =AE27*AL27 -> 10440 | AY27: =AF27*AL27 -> 7560 | AZ27: =AG27*AL27 -> 0 | BA27: =SUM(AU27:AZ27) -> 48240
A28: 15 | B28: 提供及安装风机盘管线控管道 | U28: 59 | V28: 53 | W28: 75 | X28: 53 | Y28: 75 | AA28: =SUM(T28:Z28) -> 315 | AB28: 52 | AC28: 54 | AD28: 65 | AE28: 57 | AF28: 65 | AH28: =SUM(AB28:AG28) -> 293 | AI28: set | AJ28: 70 | AK28: 75 | AL28: =AJ28+AK28 -> 145 | AM28: =T28*AL28 -> 0 | AN28: =U28*AL28 -> 8555 | AO28: =V28*AL28 -> 7685 | AP28: =W28*AL28 -> 10875 | AQ28: =X28*AL28 -> 7685 | AR28: =Y28*AL28 -> 10875 | AS28: =Z28*AL28 -> 0 | AT28: =SUM(AM28:AS28) -> 45675 | AU28: =AB28*AL28 -> 7540 | AV28: =AC28*AL28 -> 7830 | AW28: =AD28*AL28 -> 9425 | AX28: =AE28*AL28 -> 8265 | AY28: =AF28*AL28 -> 9425 | AZ28: =AG28*AL28 -> 0 | BA28: =SUM(AU28:AZ28) -> 42485
A29: 16 | B29: 提供及安装卷闸门电源 | U29: 1 | V29: 5 | W29: 7 | X29: 6 | Y29: 7 | AA29: =SUM(T29:Z29) -> 26 | AC29: 4 | AD29: 2 | AE29: 4 | AF29: 3 | AH29: =SUM(AB29:AG29) -> 13 | AI29: set | AJ29: 390 | AK29: 390 | AL29: =AJ29+AK29 -> 780 | AM29: =T29*AL29 -> 0 | AN29: =U29*AL29 -> 780 | AO29: =V29*AL29 -> 3900 | AP29: =W29*AL29 -> 5460 | AQ29: =X29*AL29 -> 4680 | AR29: =Y29*AL29 -> 5460 | AS29: =Z29*AL29 -> 0 | AT29: =SUM(AM29:AS29) -> 20280 | AU29: =AB29*AL29 -> 0 | AV29: =AC29*AL29 -> 3120 | AW29: =AD29*AL29 -> 1560 | AX29: =AE29*AL29 -> 3120 | AY29: =AF29*AL29 -> 2340 | AZ29: =AG29*AL29 -> 0 | BA29: =SUM(AU29:AZ29) -> 10140
A30: 17 | B30: 提供及安装天花强电桥架200*100 | U30: 158 | V30: 158 | W30: 158 | X30: 158 | Y30: 158 | AA30: =SUM(T30:Z30) -> 790 | AB30: 168 | AC30: 180 | AD30: 180 | AE30: 180 | AF30: 180 | AH30: =SUM(AB30:AG30) -> 888 | AI30: set | AJ30: 50 | AK30: 55 | AL30: =AJ30+AK30 -> 105 | AM30: =T30*AL30 -> 0 | AN30: =U30*AL30 -> 16590 | AO30: =V30*AL30 -> 16590 | AP30: =W30*AL30 -> 16590 | AQ30: =X30*AL30 -> 16590 | AR30: =Y30*AL30 -> 16590 | AS30: =Z30*AL30 -> 0 | AT30: =SUM(AM30:AS30) -> 82950 | AU30: =AB30*AL30 -> 17640 | AV30: =AC30*AL30 -> 18900 | AW30: =AD30*AL30 -> 18900 | AX30: =AE30*AL30 -> 18900 | AY30: =AF30*AL30 -> 18900 | AZ30: =AG30*AL30 -> 0 | BA30: =SUM(AU30:AZ30) -> 93240
A31: 18 | B31: 提供及安装地面强电桥架300*100 | U31: 175 | V31: 175 | W31: 205 | X31: 175 | Y31: 150 | AA31: =SUM(T31:Z31) -> 880 | AB31: 165 | AC31: 165 | AD31: 196 | AE31: 170 | AF31: 157 | AH31: =SUM(AB31:AG31) -> 853 | AI31: set | AJ31: 60 | AK31: 65 | AL31: =AJ31+AK31 -> 125 | AM31: =T31*AL31 -> 0 | AN31: =U31*AL31 -> 21875 | AO31: =V31*AL31 -> 21875 | AP31: =W31*AL31 -> 25625 | AQ31: =X31*AL31 -> 21875 | AR31: =Y31*AL31 -> 18750 | AS31: =Z31*AL31 -> 0 | AT31: =SUM(AM31:AS31) -> 110000 | AU31: =AB31*AL31 -> 20625 | AV31: =AC31*AL31 -> 20625 | AW31: =AD31*AL31 -> 24500 | AX31: =AE31*AL31 -> 21250 | AY31: =AF31*AL31 -> 19625 | AZ31: =AG31*AL31 -> 0 | BA31: =SUM(AU31:AZ31) -> 106625
A32: 19 | B32: 安装双鉴占用传感器管道 | U32: 41 | V32: 41 | W32: 47 | X32: 42 | Y32: 46 | AA32: =SUM(T32:Z32) -> 217 | AB32: 48 | AC32: 56 | AD32: 58 | AE32: 59 | AF32: 39 | AH32: =SUM(AB32:AG32) -> 260 | AI32: m | AJ32: 90 | AK32: 90 | AL32: =AJ32+AK32 -> 180 | AM32: =T32*AL32 -> 0 | AN32: =U32*AL32 -> 7380 | AO32: =V32*AL32 -> 7380 | AP32: =W32*AL32 -> 8460 | AQ32: =X32*AL32 -> 7560 | AR32: =Y32*AL32 -> 8280 | AS32: =Z32*AL32 -> 0 | AT32: =SUM(AM32:AS32) -> 39060 | AU32: =AB32*AL32 -> 8640 | AV32: =AC32*AL32 -> 10080 | AW32: =AD32*AL32 -> 10440 | AX32: =AE32*AL32 -> 10620 | AY32: =AF32*AL32 -> 7020 | AZ32: =AG32*AL32 -> 0 | BA32: =SUM(AU32:AZ32) -> 46800
A33: 20 | B33: 安装室外照度传感器管道 | U33: 6 | V33: 9 | W33: 11 | X33: 9 | Y33: 14 | AA33: =SUM(T33:Z33) -> 49 | AB33: 7 | AC33: 9 | AD33: 9 | AE33: 9 | AF33: 9 | AH33: =SUM(AB33:AG33) -> 43 | AI33: m | AJ33: 90 | AK33: 90 | AL33: =AJ33+AK33 -> 180 | AM33: =T33*AL33 -> 0 | AN33: =U33*AL33 -> 1080 | AO33: =V33*AL33 -> 1620 | AP33: =W33*AL33 -> 1980 | AQ33: =X33*AL33 -> 1620 | AR33: =Y33*AL33 -> 2520 | AS33: =Z33*AL33 -> 0 | AT33: =SUM(AM33:AS33) -> 8820 | AU33: =AB33*AL33 -> 1260 | AV33: =AC33*AL33 -> 1620 | AW33: =AD33*AL33 -> 1620 | AX33: =AE33*AL33 -> 1620 | AY33: =AF33*AL33 -> 1620 | AZ33: =AG33*AL33 -> 0 | BA33: =SUM(AU33:AZ33) -> 7740
A34: 21 | B34: 安装室内照度传感器管道 | U34: 25 | V34: 26 | W34: 29 | X34: 29 | Y34: 26 | AA34: =SUM(T34:Z34) -> 135 | AB34: 30 | AC34: 33 | AD34: 37 | AE34: 34 | AF34: 25 | AH34: =SUM(AB34:AG34) -> 159 | AI34: m | AJ34: 90 | AK34: 90 | AL34: =AJ34+AK34 -> 180 | AM34: =T34*AL34 -> 0 | AN34: =U34*AL34 -> 4500 | AO34: =V34*AL34 -> 4680 | AP34: =W34*AL34 -> 5220 | AQ34: =X34*AL34 -> 5220 | AR34: =Y34*AL34 -> 4680 | AS34: =Z34*AL34 -> 0 | AT34: =SUM(AM34:AS34) -> 24300 | AU34: =AB34*AL34 -> 5400 | AV34: =AC34*AL34 -> 5940 | AW34: =AD34*AL34 -> 6660 | AX34: =AE34*AL34 -> 6120 | AY34: =AF34*AL34 -> 4500 | AZ34: =AG34*AL34 -> 0 | BA34: =SUM(AU34:AZ34) -> 28620
A35: 22 | B35: 安装厂景控制面板管道 | U35: 50 | V35: 40 | W35: 46 | X35: 41 | Y35: 46 | AA35: =SUM(T35:Z35) -> 223 | AB35: 48 | AC35: 56 | AD35: 58 | AE35: 59 | AF35: 39 | AH35: =SUM(AB35:AG35) -> 260 | AI35: m | AJ35: 90 | AK35: 90 | AL35: =AJ35+AK35 -> 180 | AM35: =T35*AL35 -> 0 | AN35: =U35*AL35 -> 9000 | AO35: =V35*AL35 -> 7200 | AP35: =W35*AL35 -> 8280 | AQ35: =X35*AL35 -> 7380 | AR35: =Y35*AL35 -> 8280 | AS35: =Z35*AL35 -> 0 | AT35: =SUM(AM35:AS35) -> 40140 | AU35: =AB35*AL35 -> 8640 | AV35: =AC35*AL35 -> 10080 | AW35: =AD35*AL35 -> 10440 | AX35: =AE35*AL35 -> 10620 | AY35: =AF35*AL35 -> 7020 | AZ35: =AG35*AL35 -> 0 | BA35: =SUM(AU35:AZ35) -> 46800
A36: 23 | B36: 提供及安装BMS管道 | U36: 243 | V36: 191 | W36: 238 | X36: 205 | Y36: 194 | AA36: =SUM(T36:Z36) -> 1071 | AB36: 203 | AC36: 197 | AD36: 203 | AE36: 193 | AF36: 208 | AH36: =SUM(AB36:AG36) -> 1004 | AI36: m | AJ36: 85 | AK36: 85 | AL36: =AJ36+AK36 -> 170 | AM36: =T36*AL36 -> 0 | AN36: =U36*AL36 -> 41310 | AO36: =V36*AL36 -> 32470 | AP36: =W36*AL36 -> 40460 | AQ36: =X36*AL36 -> 34850 | AR36: =Y36*AL36 -> 32980 | AS36: =Z36*AL36 -> 0 | AT36: =SUM(AM36:AS36) -> 182070 | AU36: =AB36*AL36 -> 34510 | AV36: =AC36*AL36 -> 33490 | AW36: =AD36*AL36 -> 34510 | AX36: =AE36*AL36 -> 32810 | AY36: =AF36*AL36 -> 35360 | AZ36: =AG36*AL36 -> 0 | BA36: =SUM(AU36:AZ36) -> 170680
A37: 24 | B37: 提供及安装地面电子 风口电源 | U37: 140 | V37: 99 | W37: 117 | X37: 99 | Y37: 96 | AA37: =SUM(T37:Z37) -> 551 | AB37: 78 | AC37: 97 | AD37: 91 | AE37: 89 | AF37: 96 | AH37: =SUM(AB37:AG37) -> 451 | AI37: m | AJ37: 90 | AK37: 90 | AL37: =AJ37+AK37 -> 180 | AM37: =T37*AL37 -> 0 | AN37: =U37*AL37 -> 25200 | AO37: =V37*AL37 -> 17820 | AP37: =W37*AL37 -> 21060 | AQ37: =X37*AL37 -> 17820 | AR37: =Y37*AL37 -> 17280 | AS37: =Z37*AL37 -> 0 | AT37: =SUM(AM37:AS37) -> 99180 | AU37: =AB37*AL37 -> 14040 | AV37: =AC37*AL37 -> 17460 | AW37: =AD37*AL37 -> 16380 | AX37: =AE37*AL37 -> 16020 | AY37: =AF37*AL37 -> 17280 | AZ37: =AG37*AL37 -> 0 | BA37: =SUM(AU37:AZ37) -> 81180
A38: 25 | B38: 提供及安装电子风口控制线管道 | U38: 140 | V38: 99 | W38: 117 | X38: 99 | Y38: 96 | AA38: =SUM(T38:Z38) -> 551 | AB38: 78 | AC38: 97 | AD38: 91 | AE38: 89 | AF38: 96 | AH38: =SUM(AB38:AG38) -> 451 | AI38: m | AJ38: 70 | AK38: 75 | AL38: =AJ38+AK38 -> 145 | AM38: =T38*AL38 -> 0 | AN38: =U38*AL38 -> 20300 | AO38: =V38*AL38 -> 14355 | AP38: =W38*AL38 -> 16965 | AQ38: =X38*AL38 -> 14355 | AR38: =Y38*AL38 -> 13920 | AS38: =Z38*AL38 -> 0 | AT38: =SUM(AM38:AS38) -> 79895 | AU38: =AB38*AL38 -> 11310 | AV38: =AC38*AL38 -> 14065 | AW38: =AD38*AL38 -> 13195 | AX38: =AE38*AL38 -> 12905 | AY38: =AF38*AL38 -> 13920 | AZ38: =AG38*AL38 -> 0 | BA38: =SUM(AU38:AZ38) -> 65395
A39: 26 | B39: 提供及安装天花弱电桥架200*100 | U39: 170 | V39: 170 | W39: 170 | X39: 170 | Y39: 170 | AA39: =SUM(T39:Z39) -> 850 | AB39: 170 | AC39: 170 | AD39: 170 | AE39: 170 | AF39: 170 | AH39: =SUM(AB39:AG39) -> 850 | AI39: m | AJ39: 50 | AK39: 55 | AL39: =AJ39+AK39 -> 105 | AM39: =T39*AL39 -> 0 | AN39: =U39*AL39 -> 17850 | AO39: =V39*AL39 -> 17850 | AP39: =W39*AL39 -> 17850 | AQ39: =X39*AL39 -> 17850 | AR39: =Y39*AL39 -> 17850 | AS39: =Z39*AL39 -> 0 | AT39: =SUM(AM39:AS39) -> 89250 | AU39: =AB39*AL39 -> 17850 | AV39: =AC39*AL39 -> 17850 | AW39: =AD39*AL39 -> 17850 | AX39: =AE39*AL39 -> 17850 | AY39: =AF39*AL39 -> 17850 | AZ39: =AG39*AL39 -> 0 | BA39: =SUM(AU39:AZ39) -> 89250
A40: 27 | B40: 提供及安装地面弱电桥架400*50 | U40: 180 | V40: 180 | W40: 180 | X40: 180 | Y40: 180 | AA40: =SUM(T40:Z40) -> 900 | AB40: 180 | AC40: 180 | AD40: 180 | AE40: 180 | AF40: 180 | AH40: =SUM(AB40:AG40) -> 900 | AI40: m | AJ40: 65 | AK40: 70 | AL40: =AJ40+AK40 -> 135 | AM40: =T40*AL40 -> 0 | AN40: =U40*AL40 -> 24300 | AO40: =V40*AL40 -> 24300 | AP40: =W40*AL40 -> 24300 | AQ40: =X40*AL40 -> 24300 | AR40: =Y40*AL40 -> 24300 | AS40: =Z40*AL40 -> 0 | AT40: =SUM(AM40:AS40) -> 121500 | AU40: =AB40*AL40 -> 24300 | AV40: =AC40*AL40 -> 24300 | AW40: =AD40*AL40 -> 24300 | AX40: =AE40*AL40 -> 24300 | AY40: =AF40*AL40 -> 24300 | AZ40: =AG40*AL40 -> 0 | BA40: =SUM(AU40:AZ40) -> 121500
A41: 28 | B41: Supply and install intelligent lighting system 提供及安装智能照明系统 | AA41: =SUM(T41:Z41) -> 0 | AH41: =SUM(AB41:AG41) -> 0 | AL41: =AJ41+AK41 -> 0 | AM41: =T41*AL41 -> 0 | AN41: =U41*AL41 -> 0 | AO41: =V41*AL41 -> 0 | AP41: =W41*AL41 -> 0 | AQ41: =X41*AL41 -> 0 | AR41: =Y41*AL41 -> 0 | AS41: =Z41*AL41 -> 0 | AT41: =SUM(AM41:AS41) -> 0 | AU41: =AB41*AL41 -> 0 | AV41: =AC41*AL41 -> 0 | AW41: =AD41*AL41 -> 0 | AX41: =AE41*AL41 -> 0 | AY41: =AF41*AL41 -> 0 | AZ41: =AG41*AL41 -> 0 | BA41: =SUM(AU41:AZ41) -> 0
A42: 29 | B42: IP通讯网关模块 | U42: 1 | V42: 1 | W42: 1 | X42: 1 | Y42: 1 | AA42: =SUM(T42:Z42) -> 5 | AB42: 1 | AC42: 1 | AD42: 1 | AE42: 1 | AF42: 1 | AH42: =SUM(AB42:AG42) -> 5 | AI42: nos | AK42: 7850 | AL42: =AJ42+AK42 -> 7850 | AM42: =T42*AL42 -> 0 | AN42: =U42*AL42 -> 7850 | AO42: =V42*AL42 -> 7850 | AP42: =W42*AL42 -> 7850 | AQ42: =X42*AL42 -> 7850 | AR42: =Y42*AL42 -> 7850 | AS42: =Z42*AL42 -> 0 | AT42: =SUM(AM42:AS42) -> 39250 | AU42: =AB42*AL42 -> 7850 | AV42: =AC42*AL42 -> 7850 | AW42: =AD42*AL42 -> 7850 | AX42: =AE42*AL42 -> 7850 | AY42: =AF42*AL42 -> 7850 | AZ42: =AG42*AL42 -> 0 | BA42: =SUM(AU42:AZ42) -> 39250
A43: 30 | B43: 系统电源模块 | U43: 5 | V43: 5 | W43: 5 | X43: 5 | Y43: 5 | AA43: =SUM(T43:Z43) -> 25 | AB43: 5 | AC43: 5 | AD43: 5 | AE43: 5 | AF43: 5 | AH43: =SUM(AB43:AG43) -> 25 | AI43: nos | AK43: 4120 | AL43: =AJ43+AK43 -> 4120 | AM43: =T43*AL43 -> 0 | AN43: =U43*AL43 -> 20600 | AO43: =V43*AL43 -> 20600 | AP43: =W43*AL43 -> 20600 | AQ43: =X43*AL43 -> 20600 | AR43: =Y43*AL43 -> 20600 | AS43: =Z43*AL43 -> 0 | AT43: =SUM(AM43:AS43) -> 103000 | AU43: =AB43*AL43 -> 20600 | AV43: =AC43*AL43 -> 20600 | AW43: =AD43*AL43 -> 20600 | AX43: =AE43*AL43 -> 20600 | AY43: =AF43*AL43 -> 20600 | AZ43: =AG43*AL43 -> 0 | BA43: =SUM(AU43:AZ43) -> 103000
A44: 31 | B44: 线路/支线耦合器 | U44: 4 | V44: 4 | W44: 4 | X44: 4 | Y44: 4 | AA44: =SUM(T44:Z44) -> 20 | AB44: 4 | AC44: 4 | AD44: 4 | AE44: 4 | AF44: 4 | AH44: =SUM(AB44:AG44) -> 20 | AI44: nos | AK44: 5300 | AL44: =AJ44+AK44 -> 5300 | AM44: =T44*AL44 -> 0 | AN44: =U44*AL44 -> 21200 | AO44: =V44*AL44 -> 21200 | AP44: =W44*AL44 -> 21200 | AQ44: =X44*AL44 -> 21200 | AR44: =Y44*AL44 -> 21200 | AS44: =Z44*AL44 -> 0 | AT44: =SUM(AM44:AS44) -> 106000 | AU44: =AB44*AL44 -> 21200 | AV44: =AC44*AL44 -> 21200 | AW44: =AD44*AL44 -> 21200 | AX44: =AE44*AL44 -> 21200 | AY44: =AF44*AL44 -> 21200 | AZ44: =AG44*AL44 -> 0 | BA44: =SUM(AU44:AZ44) -> 106000
...

Sheet HYE-option
A2: Bill of Quantity for Build General Contractor Works
A3: =[41]Summary!A2 -> CHN, Shanghai Campus Building 1 RF Project
A4: =[41]Summary!A4 -> Issue Date: 2026/08/04
A6: Name of Tenderer:____HYE________________________________
A8: DO NOT change the form of this Schdule of Rates, any changes or ideas please use "Please specify" rows 不要自行更改或修改表格格式，任何改动需使用”请列明“行
A10: No. 序号 | B10: DESCRIPTION OF WORKS 描述 | C10: Material Code 材料编号 | D10: Spec.Brand 品牌型号 | E10: Refer. Quantity/参考数量 | T10: Tender Quantity/ 投标数量 | AI10: Unit 单位 | AJ10: Unit Rate(¥) 单价 | AM10: Total(RMB)/ 合计 | AU10: Total(RMB)/ 合计 | BB10: Remarks 备注
E11: Phase 1 短翼 | M11: Phase 2 长翼 | T11: Phase 1 短翼 | AB11: Phase 2 长翼 | AJ11: Labor | AK11: Material | AL11: Total | AM11: Phase 1 短翼 | AU11: Phase 2 长翼
E12: -1F | F12: 1F | G12: 2F | H12: 3F | I12: 4F | J12: 5F | K12: Roof | L12: Total | M12: 1F | N12: 2F | O12: 3F | P12: 4F | Q12: 5F | R12: Roof | S12: Total | T12: -1F | U12: 1F | V12: 2F | W12: 3F | X12: 4F | Y12: 5F | Z12: Roof | AA12: Total | AB12: 1F | AC12: 2F | AD12: 3F | AE12: 4F | AF12: 5F | AG12: Roof | AH12: Total | AJ12: 人工 | AK12: 材料 | AL12: 小计 | AM12: -1F | AN12: 1F | AO12: 2F | AP12: 3F | AQ12: 4F | AR12: 5F | AS12: Roof | AT12: Total | AU12: 1F | AV12: 2F | AW12: 3F | AX12: 4F | AY12: 5F | AZ12: Roof | BA12: Total
A13: 1 | B13: Air-conditioning Works 空调工程
A14: 1 | B14: Ventilation System 通风系统 | L14: =SUM(F14:K14) -> 0 | S14: =SUM(M14:R14) -> 0 | T14: 0 | Z14: 0 | AA14: =SUM(T14:Z14) -> 0 | AG14: 0 | AH14: =SUM(AB14:AG14) -> 0 | AL14: =AJ14+AK14 -> 0 | AM14: =T14*AL14 -> 0 | AN14: =U14*AL14 -> 0 | AO14: =V14*AL14 -> 0 | AP14: =W14*AL14 -> 0 | AQ14: =X14*AL14 -> 0 | AR14: =Y14*AL14 -> 0 | AS14: =Z14*AL14 -> 0 | AT14: =SUM(AM14:AS14) -> 0 | AU14: =AB14*AL14 -> 0 | AV14: =AC14*AL14 -> 0 | AW14: =AD14*AL14 -> 0 | AX14: =AE14*AL14 -> 0 | AY14: =AF14*AL14 -> 0 | AZ14: =AG14*AL14 -> 0 | BA14: =SUM(AU14:AZ14) -> 0
A15: 1.01 | B15: FCP控制箱(安装于机房) 3块Flexface电子板 3组出回风感应器 | L15: =SUM(F15:K15) -> 0 | S15: =SUM(M15:R15) -> 0 | T15: 0 | U15: 1 | V15: 1 | W15: 1 | X15: 1 | Y15: 1 | Z15: 0 | AA15: =SUM(T15:Z15) -> 5 | AB15: 1 | AC15: 1 | AD15: 1 | AE15: 1 | AF15: 1 | AG15: 0 | AH15: =SUM(AB15:AG15) -> 5 | AI15: set | AJ15: 122500 | AL15: =AJ15+AK15 -> 122500 | AM15: =T15*AL15 -> 0 | AN15: =U15*AL15 -> 122500 | AO15: =V15*AL15 -> 122500 | AP15: =W15*AL15 -> 122500 | AQ15: =X15*AL15 -> 122500 | AR15: =Y15*AL15 -> 122500 | AS15: =Z15*AL15 -> 0 | AT15: =SUM(AM15:AS15) -> 612500 | AU15: =AB15*AL15 -> 122500 | AV15: =AC15*AL15 -> 122500 | AW15: =AD15*AL15 -> 122500 | AX15: =AE15*AL15 -> 122500 | AY15: =AF15*AL15 -> 122500 | AZ15: =AG15*AL15 -> 0 | BA15: =SUM(AU15:AZ15) -> 612500
A16: 1.02 | B16: FCP控制箱(安装于机房) 2块Flexface电子板 2组出回风感应器 1个 Flexmatic Touch Controller w/ BMS | L16: =SUM(F16:K16) -> 0 | S16: =SUM(M16:R16) -> 0 | T16: 0 | U16: 1 | V16: 1 | W16: 1 | X16: 1 | Y16: 1 | Z16: 0 | AA16: =SUM(T16:Z16) -> 5 | AB16: 1 | AC16: 1 | AD16: 1 | AE16: 1 | AF16: 1 | AG16: 0 | AH16: =SUM(AB16:AG16) -> 5 | AI16: set | AJ16: 111250 | AL16: =AJ16+AK16 -> 111250 | AM16: =T16*AL16 -> 0 | AN16: =U16*AL16 -> 111250 | AO16: =V16*AL16 -> 111250 | AP16: =W16*AL16 -> 111250 | AQ16: =X16*AL16 -> 111250 | AR16: =Y16*AL16 -> 111250 | AS16: =Z16*AL16 -> 0 | AT16: =SUM(AM16:AS16) -> 556250 | AU16: =AB16*AL16 -> 111250 | AV16: =AC16*AL16 -> 111250 | AW16: =AD16*AL16 -> 111250 | AX16: =AE16*AL16 -> 111250 | AY16: =AF16*AL16 -> 111250 | AZ16: =AG16*AL16 -> 0 | BA16: =SUM(AU16:AZ16) -> 556250
L17: =SUM(F17:K17) -> 0 | S17: =SUM(M17:R17) -> 0 | T17: 0 | Z17: 0 | AA17: =SUM(T17:Z17) -> 0 | AG17: 0 | AH17: =SUM(AB17:AG17) -> 0 | AL17: =AJ17+AK17 -> 0 | AM17: =T17*AL17 -> 0 | AN17: =U17*AL17 -> 0 | AO17: =V17*AL17 -> 0 | AP17: =W17*AL17 -> 0 | AQ17: =X17*AL17 -> 0 | AR17: =Y17*AL17 -> 0 | AS17: =Z17*AL17 -> 0 | AT17: =SUM(AM17:AS17) -> 0 | AU17: =AB17*AL17 -> 0 | AV17: =AC17*AL17 -> 0 | AW17: =AD17*AL17 -> 0 | AX17: =AE17*AL17 -> 0 | AY17: =AF17*AL17 -> 0 | AZ17: =AG17*AL17 -> 0 | BA17: =SUM(AU17:AZ17) -> 0
L18: =SUM(F18:K18) -> 0 | S18: =SUM(M18:R18) -> 0 | T18: 0 | Z18: 0 | AA18: =SUM(T18:Z18) -> 0 | AG18: 0 | AH18: =SUM(AB18:AG18) -> 0 | AL18: =AJ18+AK18 -> 0 | AM18: =SUBTOTAL(9,AM13:AM16) -> 0 | AN18: =SUBTOTAL(9,AN13:AN16) -> 233750 | AO18: =SUBTOTAL(9,AO13:AO16) -> 233750 | AP18: =SUBTOTAL(9,AP13:AP16) -> 233750 | AQ18: =SUBTOTAL(9,AQ13:AQ16) -> 233750 | AR18: =SUBTOTAL(9,AR13:AR16) -> 233750 | AS18: =SUBTOTAL(9,AS13:AS16) -> 0 | AT18: =SUBTOTAL(9,AT13:AT16) -> 1168750 | ... BA18: =SUBTOTAL(9,BA13:BA16) -> 1168750
L19: =SUM(F19:K19) -> 0 | S19: =SUM(M19:R19) -> 0 | T19: 0 | Z19: 0 | AA19: =SUM(T19:Z19) -> 0 | AG19: 0 | AH19: =SUM(AB19:AG19) -> 0 | AL19: =AJ19+AK19 -> 0 | AM19: =T19*AL19 -> 0 | AN19: =U19*AL19 -> 0 | AO19: =V19*AL19 -> 0 | AP19: =W19*AL19 -> 0 | AQ19: =X19*AL19 -> 0 | AR19: =Y19*AL19 -> 0 | AS19: =Z19*AL19 -> 0 | AT19: =SUM(AM19:AS19) -> 0 | AU19: =AB19*AL19 -> 0 | AV19: =AC19*AL19 -> 0 | AW19: =AD19*AL19 -> 0 | AX19: =AE19*AL19 -> 0 | AY19: =AF19*AL19 -> 0 | AZ19: =AG19*AL19 -> 0 | BA19: =SUM(AU19:AZ19) -> 0
A20: 2 | B20: Diesel generator muffler for noise reduction-柴油发电机吸降噪百叶
A21: 2.01 | B21: Provide and install diesel generator mufflers for noise reduction 提供及安装柴油发电机吸降噪百叶 | L21: =SUM(F21:K21) -> 0 | S21: =SUM(M21:R21) -> 0 | T21: 0 | U21: 108 | Z21: 0 | AA21: =SUM(T21:Z21) -> 108 | AG21: 0 | AH21: =SUM(AB21:AG21) -> 0 | AI21: sm | AJ21: 250 | AK21: 1130 | AL21: =AJ21+AK21 -> 1380 | AM21: =T21*AL21 -> 0 | AN21: =U21*AL21 -> 149040 | AO21: =V21*AL21 -> 0 | AP21: =W21*AL21 -> 0 | AQ21: =X21*AL21 -> 0 | AR21: =Y21*AL21 -> 0 | AS21: =Z21*AL21 -> 0 | AT21: =SUM(AM21:AS21) -> 149040 | AU21: =AB21*AL21 -> 0 | AV21: =AC21*AL21 -> 0 | AW21: =AD21*AL21 -> 0 | AX21: =AE21*AL21 -> 0 | AY21: =AF21*AL21 -> 0 | AZ21: =AG21*AL21 -> 0 | BA21: =SUM(AU21:AZ21) -> 0
L22: =SUM(F22:K22) -> 0 | S22: =SUM(M22:R22) -> 0 | T22: 0 | Z22: 0 | AA22: =SUM(T22:Z22) -> 0 | AG22: 0 | AH22: =SUM(AB22:AG22) -> 0 | AL22: =AJ22+AK22 -> 0 | AM22: =T22*AL22 -> 0 | AN22: =U22*AL22 -> 0 | AO22: =V22*AL22 -> 0 | AP22: =W22*AL22 -> 0 | AQ22: =X22*AL22 -> 0 | AR22: =Y22*AL22 -> 0 | AS22: =Z22*AL22 -> 0 | AT22: =SUM(AM22:AS22) -> 0 | AU22: =AB22*AL22 -> 0 | AV22: =AC22*AL22 -> 0 | AW22: =AD22*AL22 -> 0 | AX22: =AE22*AL22 -> 0 | AY22: =AF22*AL22 -> 0 | AZ22: =AG22*AL22 -> 0 | BA22: =SUM(AU22:AZ22) -> 0
L23: =SUM(F23:K23) -> 0 | S23: =SUM(M23:R23) -> 0 | T23: 0 | Z23: 0 | AA23: =SUM(T23:Z23) -> 0 | AG23: 0 | AH23: =SUM(AB23:AG23) -> 0 | AL23: =AJ23+AK23 -> 0 | AM23: =T23*AL23 -> 0 | AN23: =U23*AL23 -> 0 | AO23: =V23*AL23 -> 0 | AP23: =W23*AL23 -> 0 | AQ23: =X23*AL23 -> 0 | AR23: =Y23*AL23 -> 0 | AS23: =Z23*AL23 -> 0 | AT23: =SUM(AM23:AS23) -> 0 | AU23: =AB23*AL23 -> 0 | AV23: =AC23*AL23 -> 0 | AW23: =AD23*AL23 -> 0 | AX23: =AE23*AL23 -> 0 | AY23: =AF23*AL23 -> 0 | AZ23: =AG23*AL23 -> 0 | BA23: =SUM(AU23:AZ23) -> 0
L24: =SUM(F24:K24) -> 0 | S24: =SUM(M24:R24) -> 0 | T24: 0 | Z24: 0 | AA24: =SUM(T24:Z24) -> 0 | AG24: 0 | AH24: =SUM(AB24:AG24) -> 0 | AL24: =AJ24+AK24 -> 0 | AM24: =SUBTOTAL(9,AM19:AM22) -> 0 | AN24: =SUBTOTAL(9,AN19:AN22) -> 149040 | AO24: =SUBTOTAL(9,AO19:AO22) -> 0 | AP24: =SUBTOTAL(9,AP19:AP22) -> 0 | AQ24: =SUBTOTAL(9,AQ19:AQ22) -> 0 | AR24: =SUBTOTAL(9,AR19:AR22) -> 0 | AS24: =SUBTOTAL(9,AS19:AS22) -> 0 | AT24: =SUBTOTAL(9,AT19:AT23) -> 149040 | AU24: =SUBTOTAL(9,AU19:AU22) -> 0 | AV24: =SUBTOTAL(9,AV19:AV22) -> 0 | AW24: =SUBTOTAL(9,AW19:AW22) -> 0 | AX24: =SUBTOTAL(9,AX19:AX22) -> 0 | AY24: =SUBTOTAL(9,AY19:AY22) -> 0 | AZ24: =SUBTOTAL(9,AZ19:AZ22) -> 0 | BA24: =SUBTOTAL(9,BA19:BA22) -> 0
L25: =SUM(F25:K25) -> 0 | S25: =SUM(M25:R25) -> 0 | T25: 0 | Z25: 0 | AA25: =SUM(T25:Z25) -> 0 | AG25: 0 | AH25: =SUM(AB25:AG25) -> 0 | AL25: =AJ25+AK25 -> 0 | AM25: =T25*AL25 -> 0 | AN25: =U25*AL25 -> 0 | AO25: =V25*AL25 -> 0 | AP25: =W25*AL25 -> 0 | AQ25: =X25*AL25 -> 0 | AR25: =Y25*AL25 -> 0 | AS25: =Z25*AL25 -> 0 | AT25: =SUM(AM25:AS25) -> 0 | AU25: =AB25*AL25 -> 0 | AV25: =AC25*AL25 -> 0 | AW25: =AD25*AL25 -> 0 | AX25: =AE25*AL25 -> 0 | AY25: =AF25*AL25 -> 0 | AZ25: =AG25*AL25 -> 0 | BA25: =SUM(AU25:AZ25) -> 0
A26: 3 | B26: System partition sealing strip系统隔断收口条 | AA26: =SUM(T26:Z26) -> 0 | AH26: =SUM(AB26:AG26) -> 0
A27: =A26+0.01 -> 3.01 | B27: Supply and install painted metal trim for system partitions 提供及安装系统隔断烤漆金属收口条 | C27: B1 | L27: =SUM(F27:K27) -> 0 | S27: =SUM(M27:R27) -> 0 | U27: 46.392 | V27: 39.12 | W27: 32.688 | X27: 25.992 | Y27: 36.024 | AA27: =SUM(T27:Z27) -> 180.216 | AB27: 52.992 | AC27: 58.752 | AD27: 59.808 | AE27: 56.64 | AF27: 26.88 | AH27: =SUM(AB27:AG27) -> 255.072 | AI27: sm | AJ27: 108 | AK27: 72 | AL27: =AJ27+AK27 -> 180 | AM27: =T27*AL27 -> 0 | AN27: =U27*AL27 -> 8350.56 | AO27: =V27*AL27 -> 7041.6 | AP27: =W27*AL27 -> 5883.84 | AQ27: =X27*AL27 -> 4678.56 | AR27: =Y27*AL27 -> 6484.32 | AS27: =Z27*AL27 -> 0 | AT27: =SUM(AM27:AS27) -> 32438.88 | AU27: =AB27*AL27 -> 9538.56 | AV27: =AC27*AL27 -> 10575.36 | AW27: =AD27*AL27 -> 10765.44 | AX27: =AE27*AL27 -> 10195.2 | AY27: =AF27*AL27 -> 4838.4 | AZ27: =AG27*AL27 -> 0 | BA27: =SUM(AU27:AZ27) -> 45912.96 | BD27: =1217*180 -> 219060
A28: =A27+0.01 -> 3.02 | B28: Supply and install painted metal trim for fire-rated system partitions 提供及安装防火系统隔断烤漆金属收口条 | C28: B2 | L28: =SUM(F28:K28) -> 0 | S28: =SUM(M28:R28) -> 0 | U28: 32.424 | V28: 28.128 | W28: 36.48 | X28: 26.16 | Y28: 47.208 | AA28: =SUM(T28:Z28) -> 170.4 | AB28: 34.32 | AC28: 47.112 | AD28: 68.496 | AE28: 61.8 | AF28: 50.448 | AH28: =SUM(AB28:AG28) -> 262.176 | AI28: sm | AJ28: 108 | AK28: 72 | AL28: =AJ28+AK28 -> 180 | AM28: =T28*AL28 -> 0 | AN28: =U28*AL28 -> 5836.32 | AO28: =V28*AL28 -> 5063.04 | AP28: =W28*AL28 -> 6566.4 | AQ28: =X28*AL28 -> 4708.8 | AR28: =Y28*AL28 -> 8497.44 | AS28: =Z28*AL28 -> 0 | AT28: =SUM(AM28:AS28) -> 30672 | AU28: =AB28*AL28 -> 6177.6 | AV28: =AC28*AL28 -> 8480.16 | AW28: =AD28*AL28 -> 12329.28 | AX28: =AE28*AL28 -> 11124 | AY28: =AF28*AL28 -> 9080.64 | AZ28: =AG28*AL28 -> 0 | BA28: =SUM(AU28:AZ28) -> 47191.68
A29: =A28+0.01 -> 3.03 | B29: Supply and install painted metal trim for system glass doors 提供及安装系统玻璃门烤漆金属收口条 | C29: D1a | L29: =SUM(F29:K29) -> 0 | S29: =SUM(M29:R29) -> 0 | U29: 23 | V29: 25 | W29: 29 | X29: 25 | Y29: 33 | AA29: =SUM(T29:Z29) -> 135 | AB29: 36 | AC29: 43 | AD29: 46 | AE29: 46 | AF29: 32 | AH29: =SUM(AB29:AG29) -> 203 | AI29: sm | AJ29: 108 | AK29: 72 | AL29: =AJ29+AK29 -> 180 | AM29: =T29*AL29 -> 0 | AN29: =U29*AL29 -> 4140 | AO29: =V29*AL29 -> 4500 | AP29: =W29*AL29 -> 5220 | AQ29: =X29*AL29 -> 4500 | AR29: =Y29*AL29 -> 5940 | AS29: =Z29*AL29 -> 0 | AT29: =SUM(AM29:AS29) -> 24300 | AU29: =AB29*AL29 -> 6480 | AV29: =AC29*AL29 -> 7740 | AW29: =AD29*AL29 -> 8280 | AX29: =AE29*AL29 -> 8280 | AY29: =AF29*AL29 -> 5760 | AZ29: =AG29*AL29 -> 0 | BA29: =SUM(AU29:AZ29) -> 36540
A30: =A29+0.01 -> 3.04 | B30: Supply and install painted metal trim for system glass doors 提供及安装系统玻璃门烤漆金属收口条 | C30: D1b | L30: =SUM(F30:K30) -> 0 | S30: =SUM(M30:R30) -> 0 | U30: 3 | V30: 2 | W30: 2 | X30: 2 | Y30: 2 | AA30: =SUM(T30:Z30) -> 11 | AH30: =SUM(AB30:AG30) -> 0 | AI30: sm | AJ30: 108 | AK30: 72 | AL30: =AJ30+AK30 -> 180 | AM30: =T30*AL30 -> 0 | AN30: =U30*AL30 -> 540 | AO30: =V30*AL30 -> 360 | AP30: =W30*AL30 -> 360 | AQ30: =X30*AL30 -> 360 | AR30: =Y30*AL30 -> 360 | AS30: =Z30*AL30 -> 0 | AT30: =SUM(AM30:AS30) -> 1980 | AU30: =AB30*AL30 -> 0 | AV30: =AC30*AL30 -> 0 | AW30: =AD30*AL30 -> 0 | AX30: =AE30*AL30 -> 0 | AY30: =AF30*AL30 -> 0 | AZ30: =AG30*AL30 -> 0 | BA30: =SUM(AU30:AZ30) -> 0
L31: =SUM(F31:K31) -> 0 | S31: =SUM(M31:R31) -> 0 | T31: 0 | Z31: 0 | AA31: =SUM(T31:Z31) -> 0 | AG31: 0 | AH31: =SUM(AB31:AG31) -> 0 | AL31: =AJ31+AK31 -> 0 | AM31: =T31*AL31 -> 0 | AN31: =U31*AL31 -> 0 | AO31: =V31*AL31 -> 0 | AP31: =W31*AL31 -> 0 | AQ31: =X31*AL31 -> 0 | AR31: =Y31*AL31 -> 0 | AS31: =Z31*AL31 -> 0 | AT31: =SUM(AM31:AS31) -> 0 | AU31: =AB31*AL31 -> 0 | AV31: =AC31*AL31 -> 0 | AW31: =AD31*AL31 -> 0 | AX31: =AE31*AL31 -> 0 | AY31: =AF31*AL31 -> 0 | AZ31: =AG31*AL31 -> 0 | BA31: =SUM(AU31:AZ31) -> 0
L32: =SUM(F32:K32) -> 0 | S32: =SUM(M32:R32) -> 0 | T32: 0 | Z32: 0 | AA32: =SUM(T32:Z32) -> 0 | AG32: 0 | AH32: =SUM(AB32:AG32) -> 0 | AL32: =AJ32+AK32 -> 0 | AM32: =T32*AL32 -> 0 | AN32: =U32*AL32 -> 0 | AO32: =V32*AL32 -> 0 | AP32: =W32*AL32 -> 0 | AQ32: =X32*AL32 -> 0 | AR32: =Y32*AL32 -> 0 | AS32: =Z32*AL32 -> 0 | AT32: =SUM(AM32:AS32) -> 0 | AU32: =AB32*AL32 -> 0 | AV32: =AC32*AL32 -> 0 | AW32: =AD32*AL32 -> 0 | AX32: =AE32*AL32 -> 0 | AY32: =AF32*AL32 -> 0 | AZ32: =AG32*AL32 -> 0 | BA32: =SUM(AU32:AZ32) -> 0
L33: =SUM(F33:K33) -> 0 | S33: =SUM(M33:R33) -> 0 | T33: 0 | Z33: 0 | AA33: =SUM(T33:Z33) -> 0 | AG33: 0 | AH33: =SUM(AB33:AG33) -> 0 | AL33: =AJ33+AK33 -> 0 | AM33: =SUBTOTAL(9,AM25:AM31) -> 0 | AN33: =SUBTOTAL(9,AN25:AN31) -> 18866.88 | AO33: =SUBTOTAL(9,AO25:AO31) -> 16964.64 | AP33: =SUBTOTAL(9,AP25:AP31) -> 18030.24 | AQ33: =SUBTOTAL(9,AQ25:AQ31) -> 14247.36 | AR33: =SUBTOTAL(9,AR25:AR31) -> 21281.76 | AS33: =SUBTOTAL(9,AS25:AS31) -> 0 | AT33: =SUBTOTAL(9,AT27:AT32) -> 89390.88 | AU33: =SUBTOTAL(9,AU25:AU31) -> 22196.16 | AV33: =SUBTOTAL(9,AV25:AV31) -> 26795.52 | AW33: =SUBTOTAL(9,AW25:AW31) -> 31374.72 | AX33: =SUBTOTAL(9,AX25:AX31) -> 29599.2 | AY33: =SUBTOTAL(9,AY25:AY31) -> 19679.04 | AZ33: =SUBTOTAL(9,AZ25:AZ31) -> 0 | BA33: =SUBTOTAL(9,BA25:BA31) -> 129644.64
L34: =SUM(F34:K34) -> 0 | S34: =SUM(M34:R34) -> 0 | T34: 0 | Z34: 0 | AA34: =SUM(T34:Z34) -> 0 | AG34: 0 | AH34: =SUM(AB34:AG34) -> 0 | AL34: =AJ34+AK34 -> 0 | AM34: =T34*AL34 -> 0 | AN34: =U34*AL34 -> 0 | AO34: =V34*AL34 -> 0 | AP34: =W34*AL34 -> 0 | AQ34: =X34*AL34 -> 0 | AR34: =Y34*AL34 -> 0 | AS34: =Z34*AL34 -> 0 | AT34: =SUM(AM34:AS34) -> 0 | AU34: =AB34*AL34 -> 0 | AV34: =AC34*AL34 -> 0 | AW34: =AD34*AL34 -> 0 | AX34: =AE34*AL34 -> 0 | AY34: =AF34*AL34 -> 0 | AZ34: =AG34*AL34 -> 0 | BA34: =SUM(AU34:AZ34) -> 0
L35: =SUM(F35:K35) -> 0 | S35: =SUM(M35:R35) -> 0 | T35: 0 | Z35: 0 | AA35: =SUM(T35:Z35) -> 0 | AG35: 0 | AH35: =SUM(AB35:AG35) -> 0 | AL35: =AJ35+AK35 -> 0 | AM35: =T35*AL35 -> 0 | AN35: =U35*AL35 -> 0 | AO35: =V35*AL35 -> 0 | AP35: =W35*AL35 -> 0 | AQ35: =X35*AL35 -> 0 | AR35: =Y35*AL35 -> 0 | AS35: =Z35*AL35 -> 0 | AT35: =SUM(AM35:AS35) -> 0 | AU35: =AB35*AL35 -> 0 | AV35: =AC35*AL35 -> 0 | AW35: =AD35*AL35 -> 0 | AX35: =AE35*AL35 -> 0 | AY35: =AF35*AL35 -> 0 | AZ35: =AG35*AL35 -> 0 | BA35: =SUM(AU35:AZ35) -> 0
